<?xml version="1.0" ?>
<robot name="rrbot" >
  


 <link name="world"/>
  <!-- Base Link -->
  
  <link name="link1">
    <collision>
      <geometry>
        <box size="0.1 0.1 2"/>
      </geometry>
    </collision>

    <visual>
      <geometry>
        <box size="0.1 0.1 2"/>
      </geometry>
    </visual>

    <inertial>
      <origin rpy="0 0 0" xyz="0 0 1.0"/>
      <mass value="1"/>
      <inertia ixx="1.0" ixy="0.0" ixz="0.0" iyy="1.0" iyz="0.0" izz="1.0"/>
    </inertial>
  
  </link>

  <joint name="joint1" type="continuous">
    <parent link="world"/>
    <child link="link1"/>
    <origin rpy="0 0 0" xyz="0 0.1 1"/>
    <axis xyz="0 0 1"/>
    <dynamics damping="0.7"/>
  </joint>

  <!-- Middle Link -->
  <link name="link2">
    <collision>
      <origin rpy="0 0 0" xyz="0 0 0.45"/>
      <geometry>
        <box size="0.1 0.1 1"/>
      </geometry>
    </collision>
    <visual>
      <origin rpy="0 0 0" xyz="0 0 0.45"/>
      <geometry>
        <box size="0.1 0.1 1"/>
      </geometry>
      <material name="black"/>
    </visual>
    <inertial>
      <origin rpy="0 0 0" xyz="0 0 0.45"/>
      <mass value="1"/>
      <inertia ixx="1.0" ixy="0.0" ixz="0.0" iyy="1.0" iyz="0.0" izz="1.0"/>
    </inertial>
  </link>
  <joint name="joint2" type="continuous">
    <parent link="link1"/>
    <child link="link2"/>
    <origin rpy="0 0 0" xyz="0 0.1 0.9"/>
    <axis xyz="0 1 0"/>
    <dynamics damping="0.7"/>
  </joint>


<gazebo>
  <plugin name="gazebo_ros2_control"      filename="libgazebo_ros2_control.so">
     <robot_sim_type>gazebo_ros2_control/DefaultRobotHWSim     </robot_sim_type>
     <robotNamespace>/rrbot     </robotNamespace>
    <parameters>$(find autonomous_rover)/controllers/control_me.yaml  </parameters>
    <control_period>0.01</control_period>
    <e_stop_topic>/estop</e_stop_topic>
  </plugin>
</gazebo>
<!-- EffortJointInterface -->
<transmission name="Transmission_1">
  <type>transmission_interface/SimpleTransmission</type>
  <joint name="joint1">
    <hardwareInterface> hardware_interface/PositionJointInterface  </hardwareInterface>
  </joint>
  <actuator name="base_motor">
    <hardwareInterface>      hardware_interface/PositionJointInterface    </hardwareInterface>
    <mechanicalReduction>1</mechanicalReduction>
  </actuator>
</transmission>



<transmission name="Transmission_2">
  <type>transmission_interface/SimpleTransmission</type>
  <joint name="joint2">
    <hardwareInterface> hardware_interface/PositionJointInterface  </hardwareInterface>
  </joint>
  <actuator name="mid">
    <hardwareInterface>      hardware_interface/PositionJointInterface    </hardwareInterface>
    <mechanicalReduction>1</mechanicalReduction>
  </actuator>
</transmission>


<!-- </transmission>
  <transmission name="tran2">
    <type>transmission_interface/SimpleTransmission</type>
    <joint name="joint2"/>
    <actuator name="motor2">
      <hardwareInterface>EffortJointInterface</hardwareInterface>
      <mechanicalReduction>1</mechanicalReduction>
    </actuator> -->



  



</robot>
